Workbook

Sheet Client Subscriptions
A1: Client Email | B1: Product | C1: Plan | D1: Start Date | E1: Expiry Date | F1: Days Left | G1: Cost Price | H1: Selling Price | I1: Profit | J1: Payment Status | K1: Payment Date | L1: Renewal Status | M1: Account Type | N1: Payment Method | O1: Notes | T1: Plan | U1: Days
A2: arzhang.china7@outlook.com | B2: chatgpt | C2: 1 Month | D2: 46100 | E2: =IF(C2<>"",D2+VLOOKUP(C2,$T$2:$U$6,2,FALSE),"") -> 46130 | F2: =IF(E2<>"",E2-TODAY(),"") -> 23 | G2: 5 | H2: 35 | I2: =IF(H2<>"",H2-G2,"") -> 30 | J2: Paid | K2: =IF(J2<>"",TODAY(),"") -> 46107 | L2: Renewed | M2: Private | N2: WeChat | O2: 2 | T2: 1 Month | U2: 30
A3: yooolozin@gmail.com | B3: chatgpt | C3: 1 Month | D3: 46101 | E3: =IF(C3<>"",D3+VLOOKUP(C3,$T$2:$U$6,2,FALSE),"") -> 46131 | F3: =IF(E3<>"",E3-TODAY(),"") -> 24 | G3: 5 | H3: 35 | I3: =IF(H3<>"",H3-G3,"") -> 30 | J3: Pending | K3: =IF(J3<>"",TODAY(),"") -> 46107 | L3: Renewed | M3: Private | N3: WeChat | O3: 2 | T3: 2 Months | U3: 60
A4: 8216me@gmail.com | B4: chatgpt | C4: 1 Month | D4: 46101 | E4: =IF(C4<>"",D4+VLOOKUP(C4,$T$2:$U$6,2,FALSE),"") -> 46131 | F4: =IF(E4<>"",E4-TODAY(),"") -> 24 | G4: 5 | H4: 35 | I4: =IF(H4<>"",H4-G4,"") -> 30 | J4: Paid | K4: =IF(J4<>"",TODAY(),"") -> 46107 | L4: Renewed | M4: Private | N4: WeChat | O4: 2 | T4: 3 Months | U4: 90
A5: Aymane.chergui.aymanox@gmail.com | B5: chatgpt | C5: 1 Month | D5: 46101 | E5: =IF(C5<>"",D5+VLOOKUP(C5,$T$2:$U$6,2,FALSE),"") -> 46131 | F5: =IF(E5<>"",E5-TODAY(),"") -> 24 | G5: 5 | H5: 35 | I5: =IF(H5<>"",H5-G5,"") -> 30 | J5: Paid | K5: =IF(J5<>"",TODAY(),"") -> 46107 | L5: Renewed | M5: Private | N5: WeChat | O5: 2 | T5: 6 Months | U5: 180
A6: Hassanagoujgal72@gmail.com | B6: canva | C6: 1 Year | D6: 46074 | E6: =IF(C6<>"",D6+VLOOKUP(C6,$T$2:$U$6,2,FALSE),"") -> 46439 | F6: =IF(E6<>"",E6-TODAY(),"") -> 332 | G6: 5 | H6: 60 | I6: =IF(H6<>"",H6-G6,"") -> 55 | J6: Paid | K6: =IF(J6<>"",TODAY(),"") -> 46107 | L6: Renewed | M6: Private | N6: WeChat | T6: 1 Year | U6: 365
A7: pbqepyv99@outlook.com | B7: chatgpt | C7: 1 Year | D7: 46074 | E7: =IF(C7<>"",D7+VLOOKUP(C7,$T$2:$U$6,2,FALSE),"") -> 46439 | F7: =IF(E7<>"",E7-TODAY(),"") -> 332 | G7: 40 | H7: 300 | I7: =IF(H7<>"",H7-G7,"") -> 260 | J7: Paid | K7: =IF(J7<>"",TODAY(),"") -> 46107 | L7: Renewed | M7: Private | N7: WeChat
A8: klvcxsm620@outlook.com | B8: chatgpt | C8: 1 Year | D8: 46074 | E8: =IF(C8<>"",D8+VLOOKUP(C8,$T$2:$U$6,2,FALSE),"") -> 46439 | F8: =IF(E8<>"",E8-TODAY(),"") -> 332 | G8: 40 | H8: 300 | I8: =IF(H8<>"",H8-G8,"") -> 260 | J8: Paid | K8: =IF(J8<>"",TODAY(),"") -> 46107 | L8: Renewed | M8: Private | N8: WeChat
A9: mazforge01@gmail.com | B9: chatgpt | C9: 1 Month | D9: 46074 | E9: =IF(C9<>"",D9+VLOOKUP(C9,$T$2:$U$6,2,FALSE),"") -> 46104 | F9: =IF(E9<>"",E9-TODAY(),"") -> -3 | G9: 5 | H9: 35 | I9: =IF(H9<>"",H9-G9,"") -> 30 | J9: Paid | K9: =IF(J9<>"",TODAY(),"") -> 46107 | L9: Renewed | M9: Private | N9: WeChat
A10: mazforge01@gmail.com | B10: perplexity ai | C10: 1 Month | D10: 46074 | E10: =IF(C10<>"",D10+VLOOKUP(C10,$T$2:$U$6,2,FALSE),"") -> 46104 | F10: =IF(E10<>"",E10-TODAY(),"") -> -3 | G10: 15 | H10: 40 | I10: =IF(H10<>"",H10-G10,"") -> 25 | J10: Paid | K10: =IF(J10<>"",TODAY(),"") -> 46107 | L10: Renewed | M10: Private | N10: WeChat
A11: Artemvolodaskiss@icloud.com | B11: chatgpt | C11: 1 Month | D11: 46100 | E11: =IF(C11<>"",D11+VLOOKUP(C11,$T$2:$U$6,2,FALSE),"") -> 46130 | F11: =IF(E11<>"",E11-TODAY(),"") -> 23 | G11: 5 | H11: 35 | I11: =IF(H11<>"",H11-G11,"") -> 30 | J11: Paid | K11: =IF(J11<>"",TODAY(),"") -> 46107 | L11: Renewed | M11: Private | N11: WeChat | O11: 2
A12: mggg7132@gmail.com | B12: chatgpt | C12: 1 Month | D12: 46100 | E12: =IF(C12<>"",D12+VLOOKUP(C12,$T$2:$U$6,2,FALSE),"") -> 46130 | F12: =IF(E12<>"",E12-TODAY(),"") -> 23 | G12: 5 | H12: 35 | I12: =IF(H12<>"",H12-G12,"") -> 30 | J12: Paid | K12: =IF(J12<>"",TODAY(),"") -> 46107 | L12: Renewed | M12: Private | N12: WeChat | O12: 2
A13: driss.1427@gmail.com | B13: IPTV | C13: 1 Year | D13: 46074 | E13: =IF(C13<>"",D13+VLOOKUP(C13,$T$2:$U$6,2,FALSE),"") -> 46439 | F13: =IF(E13<>"",E13-TODAY(),"") -> 332 | G13: 70 | H13: 200 | I13: =IF(H13<>"",H13-G13,"") -> 130 | J13: Paid | K13: =IF(J13<>"",TODAY(),"") -> 46107 | L13: Renewed | M13: Private | N13: WeChat
A14: Kostyaanna@gmail.com | B14: chatgpt | C14: 1 Month | D14: 46099 | E14: =IF(C14<>"",D14+VLOOKUP(C14,$T$2:$U$6,2,FALSE),"") -> 46129 | F14: =IF(E14<>"",E14-TODAY(),"") -> 22 | G14: 10 | H14: 70 | I14: =IF(H14<>"",H14-G14,"") -> 60 | J14: Paid | K14: =IF(J14<>"",TODAY(),"") -> 46107 | L14: Renewed | M14: Private | N14: WeChat | O14: 2
A15: radzapovakarina020@gmail.com | B15: chatgpt | C15: 1 Month | D15: =D14 -> 46099 | E15: =IF(C15<>"",D15+VLOOKUP(C15,$T$2:$U$6,2,FALSE),"") -> 46129 | F15: =IF(E15<>"",E15-TODAY(),"") -> 22 | G15: 5 | H15: 35 | I15: =IF(H15<>"",H15-G15,"") -> 30 | J15: Paid | K15: =IF(J15<>"",TODAY(),"") -> 46107 | L15: Renewed | M15: Private | N15: WeChat
A16: badr400000@gmail.com | B16: chatgpt | C16: 1 Month | D16: 46076 | E16: =IF(C16<>"",D16+VLOOKUP(C16,$T$2:$U$6,2,FALSE),"") -> 46106 | F16: =IF(E16<>"",E16-TODAY(),"") -> -1 | G16: 5 | H16: 35 | I16: =IF(H16<>"",H16-G16,"") -> 30 | J16: Paid | K16: =IF(J16<>"",TODAY(),"") -> 46107 | L16: Renewed | M16: Private | N16: WeChat
A17: amponsahrichard49@gmail.com | B17: chatgpt | C17: 1 Month | D17: 46076 | E17: =IF(C17<>"",D17+VLOOKUP(C17,$T$2:$U$6,2,FALSE),"") -> 46106 | F17: =IF(E17<>"",E17-TODAY(),"") -> -1 | G17: 5 | H17: 35 | I17: =IF(H17<>"",H17-G17,"") -> 30 | J17: Paid | K17: =IF(J17<>"",TODAY(),"") -> 46107 | L17: Renewed | M17: Private | N17: WeChat
A18: ghalebsaleh221@gmail.com | B18: chatgpt | C18: 1 Month | D18: 46076 | E18: =IF(C18<>"",D18+VLOOKUP(C18,$T$2:$U$6,2,FALSE),"") -> 46106 | F18: =IF(E18<>"",E18-TODAY(),"") -> -1 | G18: 5 | H18: 35 | I18: =IF(H18<>"",H18-G18,"") -> 30 | J18: Paid | K18: =IF(J18<>"",TODAY(),"") -> 46107 | L18: Renewed | M18: Private | N18: WeChat
A19: elmounchitwiame@gmail.com | B19: chatgpt | C19: 1 Month | D19: 46099 | E19: =IF(C19<>"",D19+VLOOKUP(C19,$T$2:$U$6,2,FALSE),"") -> 46129 | F19: =IF(E19<>"",E19-TODAY(),"") -> 22 | G19: 5 | H19: 35 | I19: =IF(H19<>"",H19-G19,"") -> 30 | J19: Paid | K19: =IF(J19<>"",TODAY(),"") -> 46107 | L19: Renewed | M19: Private | N19: WeChat | O19: 2
A20: M.sufyan.bjut@gmail.com | B20: chatgpt | C20: 1 Month | D20: 46094 | E20: =IF(C20<>"",D20+VLOOKUP(C20,$T$2:$U$6,2,FALSE),"") -> 46124 | F20: =IF(E20<>"",E20-TODAY(),"") -> 17 | G20: 5 | H20: 35 | I20: =IF(H20<>"",H20-G20,"") -> 30 | J20: Paid | K20: =IF(J20<>"",TODAY(),"") -> 46107 | L20: Renewed | M20: Private | N20: WeChat
A21: joud.hani08@gmail.com | B21: chatgpt | C21: 1 Month | D21: 46076 | E21: =IF(C21<>"",D21+VLOOKUP(C21,$T$2:$U$6,2,FALSE),"") -> 46106 | F21: =IF(E21<>"",E21-TODAY(),"") -> -1 | G21: 5 | H21: 35 | I21: =IF(H21<>"",H21-G21,"") -> 30 | J21: Paid | K21: =IF(J21<>"",TODAY(),"") -> 46107 | L21: Renewed | M21: Private | N21: WeChat
A22: bakrazaroual@icloud.com | B22: VPN | C22: 1 Year | D22: 46076 | E22: =IF(C22<>"",D22+VLOOKUP(C22,$T$2:$U$6,2,FALSE),"") -> 46441 | F22: =IF(E22<>"",E22-TODAY(),"") -> 334 | G22: 20 | H22: 200 | I22: =IF(H22<>"",H22-G22,"") -> 180 | J22: Paid | K22: =IF(J22<>"",TODAY(),"") -> 46107 | L22: Renewed | M22: Private | N22: WeChat
A23: bakrazaroual@icloud.com | B23: NETFLIX | C23: 1 Month | D23: 46101 | E23: =IF(C23<>"",D23+VLOOKUP(C23,$T$2:$U$6,2,FALSE),"") -> 46131 | F23: =IF(E23<>"",E23-TODAY(),"") -> 24 | G23: 18 | H23: 30 | I23: =IF(H23<>"",H23-G23,"") -> 12 | J23: Paid | K23: =IF(J23<>"",TODAY(),"") -> 46107 | L23: Renewed | M23: Shared | N23: WeChat | O23: 2
A24: wassim.sania19@gmail.com | B24: chatgpt | C24: 1 Month | D24: 46076 | E24: =IF(C24<>"",D24+VLOOKUP(C24,$T$2:$U$6,2,FALSE),"") -> 46106 | F24: =IF(E24<>"",E24-TODAY(),"") -> -1 | G24: 5 | H24: 35 | I24: =IF(H24<>"",H24-G24,"") -> 30 | J24: Paid | K24: =IF(J24<>"",TODAY(),"") -> 46107 | L24: Renewed | M24: Private | N24: WeChat
A25: fatohe.27@gmail.com | B25: chatgpt | C25: 1 Month | D25: 46076 | E25: =IF(C25<>"",D25+VLOOKUP(C25,$T$2:$U$6,2,FALSE),"") -> 46106 | F25: =IF(E25<>"",E25-TODAY(),"") -> -1 | G25: 5 | H25: 35 | I25: =IF(H25<>"",H25-G25,"") -> 30 | J25: Paid | K25: =IF(J25<>"",TODAY(),"") -> 46107 | L25: Renewed | M25: Private | N25: WeChat
A26: engr.mustafatahir@gmail.com | B26: chatgpt | C26: 1 Month | D26: 46103 | E26: =IF(C26<>"",D26+VLOOKUP(C26,$T$2:$U$6,2,FALSE),"") -> 46133 | F26: =IF(E26<>"",E26-TODAY(),"") -> 26 | G26: 5 | H26: 35 | I26: =IF(H26<>"",H26-G26,"") -> 30 | J26: Paid | K26: =IF(J26<>"",TODAY(),"") -> 46107 | L26: Renewed | M26: Private | N26: WeChat | O26: 2
A27: mounib.bouabid2012@gmail.com | B27: chatgpt | C27: 1 Month | D27: 46076 | E27: =IF(C27<>"",D27+VLOOKUP(C27,$T$2:$U$6,2,FALSE),"") -> 46106 | F27: =IF(E27<>"",E27-TODAY(),"") -> -1 | G27: 5 | H27: 35 | I27: =IF(H27<>"",H27-G27,"") -> 30 | J27: Paid | K27: =IF(J27<>"",TODAY(),"") -> 46107 | L27: Renewed | M27: Private | N27: WeChat
A28: etudescn1@gmail.com | B28: chatgpt | C28: 1 Month | D28: 46076 | E28: =IF(C28<>"",D28+VLOOKUP(C28,$T$2:$U$6,2,FALSE),"") -> 46106 | F28: =IF(E28<>"",E28-TODAY(),"") -> -1 | G28: 5 | H28: 35 | I28: =IF(H28<>"",H28-G28,"") -> 30 | J28: Paid | K28: =IF(J28<>"",TODAY(),"") -> 46107 | L28: Renewed | M28: Private | N28: WeChat
A29: rachahaziz2@gmail.com | B29: chatgpt | C29: 1 Month | D29: 46076 | E29: =IF(C29<>"",D29+VLOOKUP(C29,$T$2:$U$6,2,FALSE),"") -> 46106 | F29: =IF(E29<>"",E29-TODAY(),"") -> -1 | G29: 5 | H29: 35 | I29: =IF(H29<>"",H29-G29,"") -> 30 | J29: Paid | K29: =IF(J29<>"",TODAY(),"") -> 46107 | L29: Renewed | M29: Private | N29: WeChat
A30: chamunokara70@gmail.com | B30: chatgpt | C30: 1 Month | D30: 46103 | E30: =IF(C30<>"",D30+VLOOKUP(C30,$T$2:$U$6,2,FALSE),"") -> 46133 | F30: =IF(E30<>"",E30-TODAY(),"") -> 26 | G30: 5 | H30: 35 | I30: =IF(H30<>"",H30-G30,"") -> 30 | J30: Paid | K30: =IF(J30<>"",TODAY(),"") -> 46107 | L30: Renewed | M30: Private | N30: WeChat | O30: 2
A31: Sakinemouha@gmail.com | B31: VPN | C31: 1 Month | D31: 46076 | E31: =IF(C31<>"",D31+VLOOKUP(C31,$T$2:$U$6,2,FALSE),"") -> 46106 | F31: =IF(E31<>"",E31-TODAY(),"") -> -1 | G31: 5 | H31: 35 | I31: =IF(H31<>"",H31-G31,"") -> 30 | J31: Paid | K31: =IF(J31<>"",TODAY(),"") -> 46107 | L31: Renewed | M31: Private | N31: WeChat
A32: bibekbamanu1@gmail.com | B32: chatgpt | C32: 1 Month | D32: 46101 | E32: =IF(C32<>"",D32+VLOOKUP(C32,$T$2:$U$6,2,FALSE),"") -> 46131 | F32: =IF(E32<>"",E32-TODAY(),"") -> 24 | G32: 5 | H32: 35 | I32: =IF(H32<>"",H32-G32,"") -> 30 | J32: Paid | K32: =IF(J32<>"",TODAY(),"") -> 46107 | L32: Renewed | M32: Private | N32: WeChat | O32: 2
A33: hindelkarrichi@gmail.com | B33: chatgpt | C33: 1 Month | D33: =IF(C33<>"",TODAY(),"") -> 46107 | E33: =IF(C33<>"",D33+VLOOKUP(C33,$T$2:$U$6,2,FALSE),"") -> 46137 | F33: =IF(E33<>"",E33-TODAY(),"") -> 30 | G33: 5 | H33: 35 | I33: =IF(H33<>"",H33-G33,"") -> 30 | J33: Paid | K33: =IF(J33<>"",TODAY(),"") -> 46107 | L33: Renewed | M33: Private | N33: WeChat
A34: asikpojessica@gmail.com | B34: chatgpt | C34: 1 Month | D34: =IF(C34<>"",TODAY(),"") -> 46107 | E34: =IF(C34<>"",D34+VLOOKUP(C34,$T$2:$U$6,2,FALSE),"") -> 46137 | F34: =IF(E34<>"",E34-TODAY(),"") -> 30 | G34: 5 | H34: 35 | I34: =IF(H34<>"",H34-G34,"") -> 30 | J34: Paid | K34: =IF(J34<>"",TODAY(),"") -> 46107 | L34: Renewed | M34: Private | N34: WeChat
A35: younglily4real@gmail.com | B35: chatgpt | C35: 1 Month | D35: =IF(C35<>"",TODAY(),"") -> 46107 | E35: =IF(C35<>"",D35+VLOOKUP(C35,$T$2:$U$6,2,FALSE),"") -> 46137 | F35: =IF(E35<>"",E35-TODAY(),"") -> 30 | G35: 5 | H35: 35 | I35: =IF(H35<>"",H35-G35,"") -> 30 | J35: Paid | K35: =IF(J35<>"",TODAY(),"") -> 46107 | L35: Renewed | M35: Private | N35: WeChat
A36: 4u4me77@gmail.com | B36: chatgpt | C36: 1 Month | D36: =IF(C36<>"",TODAY(),"") -> 46107 | E36: =IF(C36<>"",D36+VLOOKUP(C36,$T$2:$U$6,2,FALSE),"") -> 46137 | F36: =IF(E36<>"",E36-TODAY(),"") -> 30 | G36: 5 | H36: 35 | I36: =IF(H36<>"",H36-G36,"") -> 30 | J36: Paid | K36: =IF(J36<>"",TODAY(),"") -> 46107 | L36: Renewed | M36: Private | N36: WeChat
A37: buehsamuel81@gmail.com | B37: chatgpt | C37: 1 Month | D37: =IF(C37<>"",TODAY(),"") -> 46107 | E37: =IF(C37<>"",D37+VLOOKUP(C37,$T$2:$U$6,2,FALSE),"") -> 46137 | F37: =IF(E37<>"",E37-TODAY(),"") -> 30 | G37: 5 | H37: 35 | I37: =IF(H37<>"",H37-G37,"") -> 30 | J37: Paid | K37: =IF(J37<>"",TODAY(),"") -> 46107 | L37: Renewed | M37: Private | N37: WeChat
A38: Bendalhsaadeddine001@gmail.com | B38: chatgpt | C38: 1 Month | D38: =IF(C38<>"",TODAY(),"") -> 46107 | E38: =IF(C38<>"",D38+VLOOKUP(C38,$T$2:$U$6,2,FALSE),"") -> 46137 | F38: =IF(E38<>"",E38-TODAY(),"") -> 30 | G38: 5 | H38: 35 | I38: =IF(H38<>"",H38-G38,"") -> 30 | J38: Paid | K38: =IF(J38<>"",TODAY(),"") -> 46107 | L38: Renewed | M38: Private | N38: WeChat
A39: usama.crlm10@gmail.com | B39: chatgpt | C39: 1 Month | D39: =IF(C39<>"",TODAY(),"") -> 46107 | E39: =IF(C39<>"",D39+VLOOKUP(C39,$T$2:$U$6,2,FALSE),"") -> 46137 | F39: =IF(E39<>"",E39-TODAY(),"") -> 30 | G39: 5 | H39: 35 | I39: =IF(H39<>"",H39-G39,"") -> 30 | J39: Pending | K39: =IF(J39<>"",TODAY(),"") -> 46107 | L39: Renewed | M39: Private | N39: WeChat | O39: 2
A40: yassminayassmina759@gmail.com | B40: NETFLIX | C40: 1 Month | D40: 46075 | E40: =IF(C40<>"",D40+VLOOKUP(C40,$T$2:$U$6,2,FALSE),"") -> 46105 | F40: =IF(E40<>"",E40-TODAY(),"") -> -2 | G40: 18 | H40: 30 | I40: =IF(H40<>"",H40-G40,"") -> 12 | J40: Paid | K40: =IF(J40<>"",TODAY(),"") -> 46107 | L40: Renewed | M40: Shared | N40: WeChat
...

Sheet Dashboard
A1: TOTAL REVENUE | B1: =SUM('Client Subscriptions'!H:H) -> 14000
A2: TOTAL PROFIT | B2: =SUM('Client Subscriptions'!I:I) -> 11623
A3: ACTIVE SUBSCRIPTIONS | B3: =COUNTIF('Client Subscriptions'!F:F,">0") -> 283
A4: EXPIRING ≤4 DAYS | B4: =COUNTIFS('Client Subscriptions'!F:F,"<=4",'Client Subscriptions'!F:F,">0") -> 29
A5: EXPIRED | B5: =COUNTIF('Client Subscriptions'!F:F,"<=0") -> 18
A6: PENDING PAYMENTS | B6: =COUNTIF('Client Subscriptions'!J:J,"Pending") -> 13

Sheet Product Analytics
A1: Product | B1: Total Sales | C1: Total Profit
A2: Netflix | B2: =COUNTIF('Client Subscriptions'!B:B,A2) -> 6 | C2: =SUMIF('Client Subscriptions'!B:B,A2,'Client Subscriptions'!I:I) -> 101
A3: VPN | B3: =COUNTIF('Client Subscriptions'!B:B,A3) -> 16 | C3: =SUMIF('Client Subscriptions'!B:B,A3,'Client Subscriptions'!I:I) -> 577
A4: ChatGPT | B4: =COUNTIF('Client Subscriptions'!B:B,A4) -> 251 | C4: =SUMIF('Client Subscriptions'!B:B,A4,'Client Subscriptions'!I:I) -> 8965
A5: IPTV | B5: =COUNTIF('Client Subscriptions'!B:B,A5) -> 1 | C5: =SUMIF('Client Subscriptions'!B:B,A5,'Client Subscriptions'!I:I) -> 130
A6: Spotify | B6: =COUNTIF('Client Subscriptions'!B:B,A6) -> 5 | C6: =SUMIF('Client Subscriptions'!B:B,A6,'Client Subscriptions'!I:I) -> 160
A7: Canva | B7: =COUNTIF('Client Subscriptions'!B:B,A7) -> 3 | C7: =SUMIF('Client Subscriptions'!B:B,A7,'Client Subscriptions'!I:I) -> 165
A8: Apple One | B8: =COUNTIF('Client Subscriptions'!B:B,A8) -> 0 | C8: =SUMIF('Client Subscriptions'!B:B,A8,'Client Subscriptions'!I:I) -> 0
A9: perplexity ai | B9: 1 | C9: 40

Sheet Monthly Revenue
A1: Month | B1: Revenue
A2: Jan | B2: =SUMIFS('Client Subscriptions'!H:H, 'Client Subscriptions'!K:K,">="&DATE(YEAR(TODAY()),1,1), 'Client Subscriptions'!K:K,"<"&EOMONTH(DATE(YEAR(TODAY()),1,1),0)+1) -> 0
A3: Feb | B3: =SUMIFS('Client Subscriptions'!H:H, 'Client Subscriptions'!K:K,">="&DATE(YEAR(TODAY()),2,1), 'Client Subscriptions'!K:K,"<"&EOMONTH(DATE(YEAR(TODAY()),2,1),0)+1) -> 0
A4: Mar | B4: =SUMIFS('Client Subscriptions'!H:H, 'Client Subscriptions'!K:K,">="&DATE(YEAR(TODAY()),3,1), 'Client Subscriptions'!K:K,"<"&EOMONTH(DATE(YEAR(TODAY()),3,1),0)+1) -> 13940
A5: Apr | B5: =SUMIFS('Client Subscriptions'!H:H, 'Client Subscriptions'!K:K,">="&DATE(YEAR(TODAY()),4,1), 'Client Subscriptions'!K:K,"<"&EOMONTH(DATE(YEAR(TODAY()),4,1),0)+1) -> 0
A6: May | B6: =SUMIFS('Client Subscriptions'!H:H, 'Client Subscriptions'!K:K,">="&DATE(YEAR(TODAY()),5,1), 'Client Subscriptions'!K:K,"<"&EOMONTH(DATE(YEAR(TODAY()),5,1),0)+1) -> 0
A7: Jun | B7: =SUMIFS('Client Subscriptions'!H:H, 'Client Subscriptions'!K:K,">="&DATE(YEAR(TODAY()),6,1), 'Client Subscriptions'!K:K,"<"&EOMONTH(DATE(YEAR(TODAY()),6,1),0)+1) -> 0
A8: Jul | B8: =SUMIFS('Client Subscriptions'!H:H, 'Client Subscriptions'!K:K,">="&DATE(YEAR(TODAY()),7,1), 'Client Subscriptions'!K:K,"<"&EOMONTH(DATE(YEAR(TODAY()),7,1),0)+1) -> 0
A9: Aug | B9: =SUMIFS('Client Subscriptions'!H:H, 'Client Subscriptions'!K:K,">="&DATE(YEAR(TODAY()),8,1), 'Client Subscriptions'!K:K,"<"&EOMONTH(DATE(YEAR(TODAY()),8,1),0)+1) -> 0
A10: Sep | B10: =SUMIFS('Client Subscriptions'!H:H, 'Client Subscriptions'!K:K,">="&DATE(YEAR(TODAY()),9,1), 'Client Subscriptions'!K:K,"<"&EOMONTH(DATE(YEAR(TODAY()),9,1),0)+1) -> 0
A11: Oct | B11: =SUMIFS('Client Subscriptions'!H:H, 'Client Subscriptions'!K:K,">="&DATE(YEAR(TODAY()),10,1), 'Client Subscriptions'!K:K,"<"&EOMONTH(DATE(YEAR(TODAY()),10,1),0)+1) -> 0
A12: Nov | B12: =SUMIFS('Client Subscriptions'!H:H, 'Client Subscriptions'!K:K,">="&DATE(YEAR(TODAY()),11,1), 'Client Subscriptions'!K:K,"<"&EOMONTH(DATE(YEAR(TODAY()),11,1),0)+1) -> 0
A13: Dec | B13: =SUMIFS('Client Subscriptions'!H:H, 'Client Subscriptions'!K:K,">="&DATE(YEAR(TODAY()),12,1), 'Client Subscriptions'!K:K,"<"&EOMONTH(DATE(YEAR(TODAY()),12,1),0)+1) -> 0
